{
 "cells": [
  {
   "cell_type": "code",
   "execution_count": 17,
   "id": "981ddd7f",
   "metadata": {
    "scrolled": false
   },
   "outputs": [
    {
     "name": "stdout",
     "output_type": "stream",
     "text": [
      "Found 6 images belonging to 2 classes.\n",
      "Found 18 images belonging to 3 classes.\n"
     ]
    },
    {
     "name": "stderr",
     "output_type": "stream",
     "text": [
      "C:\\Users\\user\\AppData\\Local\\Temp\\ipykernel_6644\\3555544667.py:85: UserWarning: `Model.fit_generator` is deprecated and will be removed in a future version. Please use `Model.fit`, which supports generators.\n",
      "  model.fit_generator(\n"
     ]
    },
    {
     "name": "stdout",
     "output_type": "stream",
     "text": [
      "Epoch 1/10\n",
      "An error occurred: Graph execution error:\n",
      "\n",
      "Detected at node categorical_crossentropy/softmax_cross_entropy_with_logits defined at (most recent call last):\n",
      "  File \"C:\\Users\\user\\anaconda3\\lib\\runpy.py\", line 197, in _run_module_as_main\n",
      "\n",
      "  File \"C:\\Users\\user\\anaconda3\\lib\\runpy.py\", line 87, in _run_code\n",
      "\n",
      "  File \"C:\\Users\\user\\anaconda3\\lib\\site-packages\\ipykernel_launcher.py\", line 17, in <module>\n",
      "\n",
      "  File \"C:\\Users\\user\\anaconda3\\lib\\site-packages\\traitlets\\config\\application.py\", line 846, in launch_instance\n",
      "\n",
      "  File \"C:\\Users\\user\\anaconda3\\lib\\site-packages\\ipykernel\\kernelapp.py\", line 712, in start\n",
      "\n",
      "  File \"C:\\Users\\user\\anaconda3\\lib\\site-packages\\tornado\\platform\\asyncio.py\", line 199, in start\n",
      "\n",
      "  File \"C:\\Users\\user\\anaconda3\\lib\\asyncio\\base_events.py\", line 601, in run_forever\n",
      "\n",
      "  File \"C:\\Users\\user\\anaconda3\\lib\\asyncio\\base_events.py\", line 1905, in _run_once\n",
      "\n",
      "  File \"C:\\Users\\user\\anaconda3\\lib\\asyncio\\events.py\", line 80, in _run\n",
      "\n",
      "  File \"C:\\Users\\user\\anaconda3\\lib\\site-packages\\ipykernel\\kernelbase.py\", line 510, in dispatch_queue\n",
      "\n",
      "  File \"C:\\Users\\user\\anaconda3\\lib\\site-packages\\ipykernel\\kernelbase.py\", line 499, in process_one\n",
      "\n",
      "  File \"C:\\Users\\user\\anaconda3\\lib\\site-packages\\ipykernel\\kernelbase.py\", line 406, in dispatch_shell\n",
      "\n",
      "  File \"C:\\Users\\user\\anaconda3\\lib\\site-packages\\ipykernel\\kernelbase.py\", line 730, in execute_request\n",
      "\n",
      "  File \"C:\\Users\\user\\anaconda3\\lib\\site-packages\\ipykernel\\ipkernel.py\", line 390, in do_execute\n",
      "\n",
      "  File \"C:\\Users\\user\\anaconda3\\lib\\site-packages\\ipykernel\\zmqshell.py\", line 528, in run_cell\n",
      "\n",
      "  File \"C:\\Users\\user\\anaconda3\\lib\\site-packages\\IPython\\core\\interactiveshell.py\", line 2914, in run_cell\n",
      "\n",
      "  File \"C:\\Users\\user\\anaconda3\\lib\\site-packages\\IPython\\core\\interactiveshell.py\", line 2960, in _run_cell\n",
      "\n",
      "  File \"C:\\Users\\user\\anaconda3\\lib\\site-packages\\IPython\\core\\async_helpers.py\", line 78, in _pseudo_sync_runner\n",
      "\n",
      "  File \"C:\\Users\\user\\anaconda3\\lib\\site-packages\\IPython\\core\\interactiveshell.py\", line 3185, in run_cell_async\n",
      "\n",
      "  File \"C:\\Users\\user\\anaconda3\\lib\\site-packages\\IPython\\core\\interactiveshell.py\", line 3377, in run_ast_nodes\n",
      "\n",
      "  File \"C:\\Users\\user\\anaconda3\\lib\\site-packages\\IPython\\core\\interactiveshell.py\", line 3457, in run_code\n",
      "\n",
      "  File \"C:\\Users\\user\\AppData\\Local\\Temp\\ipykernel_6644\\3555544667.py\", line 98, in <module>\n",
      "\n",
      "  File \"C:\\Users\\user\\AppData\\Local\\Temp\\ipykernel_6644\\3555544667.py\", line 85, in train_model\n",
      "\n",
      "  File \"C:\\Users\\user\\anaconda3\\lib\\site-packages\\keras\\src\\engine\\training.py\", line 2913, in fit_generator\n",
      "\n",
      "  File \"C:\\Users\\user\\anaconda3\\lib\\site-packages\\keras\\src\\utils\\traceback_utils.py\", line 65, in error_handler\n",
      "\n",
      "  File \"C:\\Users\\user\\anaconda3\\lib\\site-packages\\keras\\src\\engine\\training.py\", line 1807, in fit\n",
      "\n",
      "  File \"C:\\Users\\user\\anaconda3\\lib\\site-packages\\keras\\src\\engine\\training.py\", line 1401, in train_function\n",
      "\n",
      "  File \"C:\\Users\\user\\anaconda3\\lib\\site-packages\\keras\\src\\engine\\training.py\", line 1384, in step_function\n",
      "\n",
      "  File \"C:\\Users\\user\\anaconda3\\lib\\site-packages\\keras\\src\\engine\\training.py\", line 1373, in run_step\n",
      "\n",
      "  File \"C:\\Users\\user\\anaconda3\\lib\\site-packages\\keras\\src\\engine\\training.py\", line 1151, in train_step\n",
      "\n",
      "  File \"C:\\Users\\user\\anaconda3\\lib\\site-packages\\keras\\src\\engine\\training.py\", line 1209, in compute_loss\n",
      "\n",
      "  File \"C:\\Users\\user\\anaconda3\\lib\\site-packages\\keras\\src\\engine\\compile_utils.py\", line 277, in __call__\n",
      "\n",
      "  File \"C:\\Users\\user\\anaconda3\\lib\\site-packages\\keras\\src\\losses.py\", line 143, in __call__\n",
      "\n",
      "  File \"C:\\Users\\user\\anaconda3\\lib\\site-packages\\keras\\src\\losses.py\", line 270, in call\n",
      "\n",
      "  File \"C:\\Users\\user\\anaconda3\\lib\\site-packages\\keras\\src\\losses.py\", line 2221, in categorical_crossentropy\n",
      "\n",
      "  File \"C:\\Users\\user\\anaconda3\\lib\\site-packages\\keras\\src\\backend.py\", line 5579, in categorical_crossentropy\n",
      "\n",
      "logits and labels must be broadcastable: logits_size=[6,3] labels_size=[6,2]\n",
      "\t [[{{node categorical_crossentropy/softmax_cross_entropy_with_logits}}]] [Op:__inference_train_function_3599]\n"
     ]
    },
    {
     "name": "stderr",
     "output_type": "stream",
     "text": [
      "Traceback (most recent call last):\n",
      "  File \"C:\\Users\\user\\AppData\\Local\\Temp\\ipykernel_6644\\3555544667.py\", line 98, in <module>\n",
      "    train_model()\n",
      "  File \"C:\\Users\\user\\AppData\\Local\\Temp\\ipykernel_6644\\3555544667.py\", line 85, in train_model\n",
      "    model.fit_generator(\n",
      "  File \"C:\\Users\\user\\anaconda3\\lib\\site-packages\\keras\\src\\engine\\training.py\", line 2913, in fit_generator\n",
      "    return self.fit(\n",
      "  File \"C:\\Users\\user\\anaconda3\\lib\\site-packages\\keras\\src\\utils\\traceback_utils.py\", line 70, in error_handler\n",
      "    raise e.with_traceback(filtered_tb) from None\n",
      "  File \"C:\\Users\\user\\AppData\\Roaming\\Python\\Python39\\site-packages\\tensorflow\\python\\eager\\execute.py\", line 53, in quick_execute\n",
      "    tensors = pywrap_tfe.TFE_Py_Execute(ctx._handle, device_name, op_name,\n",
      "tensorflow.python.framework.errors_impl.InvalidArgumentError: Graph execution error:\n",
      "\n",
      "Detected at node categorical_crossentropy/softmax_cross_entropy_with_logits defined at (most recent call last):\n",
      "  File \"C:\\Users\\user\\anaconda3\\lib\\runpy.py\", line 197, in _run_module_as_main\n",
      "\n",
      "  File \"C:\\Users\\user\\anaconda3\\lib\\runpy.py\", line 87, in _run_code\n",
      "\n",
      "  File \"C:\\Users\\user\\anaconda3\\lib\\site-packages\\ipykernel_launcher.py\", line 17, in <module>\n",
      "\n",
      "  File \"C:\\Users\\user\\anaconda3\\lib\\site-packages\\traitlets\\config\\application.py\", line 846, in launch_instance\n",
      "\n",
      "  File \"C:\\Users\\user\\anaconda3\\lib\\site-packages\\ipykernel\\kernelapp.py\", line 712, in start\n",
      "\n",
      "  File \"C:\\Users\\user\\anaconda3\\lib\\site-packages\\tornado\\platform\\asyncio.py\", line 199, in start\n",
      "\n",
      "  File \"C:\\Users\\user\\anaconda3\\lib\\asyncio\\base_events.py\", line 601, in run_forever\n",
      "\n",
      "  File \"C:\\Users\\user\\anaconda3\\lib\\asyncio\\base_events.py\", line 1905, in _run_once\n",
      "\n",
      "  File \"C:\\Users\\user\\anaconda3\\lib\\asyncio\\events.py\", line 80, in _run\n",
      "\n",
      "  File \"C:\\Users\\user\\anaconda3\\lib\\site-packages\\ipykernel\\kernelbase.py\", line 510, in dispatch_queue\n",
      "\n",
      "  File \"C:\\Users\\user\\anaconda3\\lib\\site-packages\\ipykernel\\kernelbase.py\", line 499, in process_one\n",
      "\n",
      "  File \"C:\\Users\\user\\anaconda3\\lib\\site-packages\\ipykernel\\kernelbase.py\", line 406, in dispatch_shell\n",
      "\n",
      "  File \"C:\\Users\\user\\anaconda3\\lib\\site-packages\\ipykernel\\kernelbase.py\", line 730, in execute_request\n",
      "\n",
      "  File \"C:\\Users\\user\\anaconda3\\lib\\site-packages\\ipykernel\\ipkernel.py\", line 390, in do_execute\n",
      "\n",
      "  File \"C:\\Users\\user\\anaconda3\\lib\\site-packages\\ipykernel\\zmqshell.py\", line 528, in run_cell\n",
      "\n",
      "  File \"C:\\Users\\user\\anaconda3\\lib\\site-packages\\IPython\\core\\interactiveshell.py\", line 2914, in run_cell\n",
      "\n",
      "  File \"C:\\Users\\user\\anaconda3\\lib\\site-packages\\IPython\\core\\interactiveshell.py\", line 2960, in _run_cell\n",
      "\n",
      "  File \"C:\\Users\\user\\anaconda3\\lib\\site-packages\\IPython\\core\\async_helpers.py\", line 78, in _pseudo_sync_runner\n",
      "\n",
      "  File \"C:\\Users\\user\\anaconda3\\lib\\site-packages\\IPython\\core\\interactiveshell.py\", line 3185, in run_cell_async\n",
      "\n",
      "  File \"C:\\Users\\user\\anaconda3\\lib\\site-packages\\IPython\\core\\interactiveshell.py\", line 3377, in run_ast_nodes\n",
      "\n",
      "  File \"C:\\Users\\user\\anaconda3\\lib\\site-packages\\IPython\\core\\interactiveshell.py\", line 3457, in run_code\n",
      "\n",
      "  File \"C:\\Users\\user\\AppData\\Local\\Temp\\ipykernel_6644\\3555544667.py\", line 98, in <module>\n",
      "\n",
      "  File \"C:\\Users\\user\\AppData\\Local\\Temp\\ipykernel_6644\\3555544667.py\", line 85, in train_model\n",
      "\n",
      "  File \"C:\\Users\\user\\anaconda3\\lib\\site-packages\\keras\\src\\engine\\training.py\", line 2913, in fit_generator\n",
      "\n",
      "  File \"C:\\Users\\user\\anaconda3\\lib\\site-packages\\keras\\src\\utils\\traceback_utils.py\", line 65, in error_handler\n",
      "\n",
      "  File \"C:\\Users\\user\\anaconda3\\lib\\site-packages\\keras\\src\\engine\\training.py\", line 1807, in fit\n",
      "\n",
      "  File \"C:\\Users\\user\\anaconda3\\lib\\site-packages\\keras\\src\\engine\\training.py\", line 1401, in train_function\n",
      "\n",
      "  File \"C:\\Users\\user\\anaconda3\\lib\\site-packages\\keras\\src\\engine\\training.py\", line 1384, in step_function\n",
      "\n",
      "  File \"C:\\Users\\user\\anaconda3\\lib\\site-packages\\keras\\src\\engine\\training.py\", line 1373, in run_step\n",
      "\n",
      "  File \"C:\\Users\\user\\anaconda3\\lib\\site-packages\\keras\\src\\engine\\training.py\", line 1151, in train_step\n",
      "\n",
      "  File \"C:\\Users\\user\\anaconda3\\lib\\site-packages\\keras\\src\\engine\\training.py\", line 1209, in compute_loss\n",
      "\n",
      "  File \"C:\\Users\\user\\anaconda3\\lib\\site-packages\\keras\\src\\engine\\compile_utils.py\", line 277, in __call__\n",
      "\n",
      "  File \"C:\\Users\\user\\anaconda3\\lib\\site-packages\\keras\\src\\losses.py\", line 143, in __call__\n",
      "\n",
      "  File \"C:\\Users\\user\\anaconda3\\lib\\site-packages\\keras\\src\\losses.py\", line 270, in call\n",
      "\n",
      "  File \"C:\\Users\\user\\anaconda3\\lib\\site-packages\\keras\\src\\losses.py\", line 2221, in categorical_crossentropy\n",
      "\n",
      "  File \"C:\\Users\\user\\anaconda3\\lib\\site-packages\\keras\\src\\backend.py\", line 5579, in categorical_crossentropy\n",
      "\n",
      "logits and labels must be broadcastable: logits_size=[6,3] labels_size=[6,2]\n",
      "\t [[{{node categorical_crossentropy/softmax_cross_entropy_with_logits}}]] [Op:__inference_train_function_3599]\n"
     ]
    }
   ],
   "source": [
    "# app.py\n",
    "from flask import Flask, render_template, request\n",
    "import os\n",
    "from PIL import Image\n",
    "import numpy as np\n",
    "from tensorflow.keras.models import Sequential\n",
    "from tensorflow.keras.layers import Dense, Flatten\n",
    "from tensorflow.keras.optimizers import Adam\n",
    "from tensorflow.keras.preprocessing.image import ImageDataGenerator\n",
    "\n",
    "app = Flask(__name__)\n",
    "\n",
    "# Training parameters\n",
    "epochs = 10\n",
    "batch_size = 32\n",
    "\n",
    "@app.route('/')\n",
    "def index():\n",
    "    return render_template('index.html')\n",
    "\n",
    "@app.route('/recommend', methods=['POST'])\n",
    "def recommend():\n",
    "    # Your existing code for getting user inputs\n",
    "    gender = request.form['gender']\n",
    "    category = request.form['category']\n",
    "    pattern_image = request.files['pattern_image']\n",
    "    measurements = request.form['measurements']\n",
    "\n",
    "    # Your existing code for preprocessing the pattern image\n",
    "    pattern = preprocess_image(pattern_image)\n",
    "\n",
    "    # Your existing code for making recommendations\n",
    "    recommendation = make_recommendation(pattern, gender, category, measurements)\n",
    "\n",
    "    return render_template('result.html', recommendation=recommendation)\n",
    "\n",
    "def preprocess_image(image):\n",
    "    # Your existing code for preprocessing the image\n",
    "    pass\n",
    "\n",
    "def make_recommendation(pattern, gender, category, measurements):\n",
    "    # Your existing code for making recommendations\n",
    "    pass\n",
    "\n",
    "def build_model(num_classes):\n",
    "    model = Sequential()\n",
    "    model.add(Dense(128, activation='relu', input_shape=(224, 224, 3)))\n",
    "    model.add(Flatten())\n",
    "    model.add(Dense(num_classes, activation='softmax'))\n",
    "    return model\n",
    "\n",
    "def train_model():\n",
    "    # Directories for male and female training data\n",
    "    male_train_data_dir = 'C:/Users/user/Documents/codes/clothpattern/style/Male'\n",
    "    female_train_data_dir = 'C:/Users/user/Documents/codes/clothpattern/style/Female'\n",
    "\n",
    "    # Create separate ImageDataGenerators for male and female data\n",
    "    male_train_datagen = ImageDataGenerator(rescale=1./255, shear_range=0.2, zoom_range=0.2, horizontal_flip=True)\n",
    "    female_train_datagen = ImageDataGenerator(rescale=1./255, shear_range=0.2, zoom_range=0.2, horizontal_flip=True)\n",
    "\n",
    "    # Flow training images in batches of batch_size using train_datagen generator\n",
    "    # Flow training images in batches of batch_size using train_datagen generator\n",
    "    male_train_generator = male_train_datagen.flow_from_directory(\n",
    "        male_train_data_dir,\n",
    "        target_size=(224, 224),\n",
    "        batch_size=batch_size,\n",
    "        class_mode='categorical',  # Make sure this is set correctly\n",
    "        classes=['Shirtandtrouser', 'shirtonly'])  # Add your class names\n",
    "\n",
    "    female_train_generator = female_train_datagen.flow_from_directory(\n",
    "        female_train_data_dir,\n",
    "        target_size=(224, 224),\n",
    "        batch_size=batch_size,\n",
    "        class_mode='categorical',  # Make sure this is set correctly\n",
    "        classes=['Gown', 'Jumpsuit', 'Skirt'])  # Add your class names\n",
    "\n",
    "\n",
    "    num_classes = 3  # Update this number based on your dataset\n",
    "\n",
    "    # Build and compile your model\n",
    "    model = build_model(num_classes)\n",
    "    model.compile(optimizer=Adam(), loss='categorical_crossentropy', metrics=['accuracy'])\n",
    "\n",
    "    # Train the model using fit_generator for each gender\n",
    "    model.fit_generator(\n",
    "        male_train_generator,\n",
    "        steps_per_epoch=len(male_train_generator),\n",
    "        epochs=epochs,\n",
    "        validation_data=female_train_generator,\n",
    "        validation_steps=len(female_train_generator))\n",
    "\n",
    "    # Save the trained model\n",
    "    model.save('your_model.h5')\n",
    "\n",
    "if __name__ == '__main__':\n",
    "    try:\n",
    "        # Uncomment the line below to train the model before running the app\n",
    "        train_model()\n",
    "        app.run(debug=True)\n",
    "    except Exception as e:\n",
    "        print(\"An error occurred:\", e)\n",
    "        import traceback\n",
    "        traceback.print_exc()\n"
   ]
  },
  {
   "cell_type": "code",
   "execution_count": 2,
   "id": "866811ab",
   "metadata": {},
   "outputs": [
    {
     "name": "stdout",
     "output_type": "stream",
     "text": [
      "TensorFlow version: 2.15.0\n",
      "NumPy version: 1.26.2\n"
     ]
    }
   ],
   "source": [
    "import tensorflow as tf\n",
    "import numpy as np\n",
    "\n",
    "print(\"TensorFlow version:\", tf.__version__)\n",
    "print(\"NumPy version:\", np.__version__)\n"
   ]
  },
  {
   "cell_type": "code",
   "execution_count": null,
   "id": "ee0dd1de",
   "metadata": {},
   "outputs": [],
   "source": []
  }
 ],
 "metadata": {
  "kernelspec": {
   "display_name": "Python 3 (ipykernel)",
   "language": "python",
   "name": "python3"
  },
  "language_info": {
   "codemirror_mode": {
    "name": "ipython",
    "version": 3
   },
   "file_extension": ".py",
   "mimetype": "text/x-python",
   "name": "python",
   "nbconvert_exporter": "python",
   "pygments_lexer": "ipython3",
   "version": "3.9.13"
  }
 },
 "nbformat": 4,
 "nbformat_minor": 5
}
